Workbook

Sheet Datos
A1: Tasa impositiva | B1: 0.35
A2: Gradiente de crecimiento ingresos | B2: 0.04 | C2: (crecimiento historico de los ingresoso de la industria)
A3: Inflación | B3: 0.035
A4: Costo de la deuda | B4: 0.2
A5: % deuda | B5: 0.3
A6: Tasa de rechazo (yield perdida) | B6: 0.05
A7: Numero de periodos | B7: 10 | C7: años
A8: Rubro / Ítem | B8: Cantidad / detalle | D8: Información Adicional | E8: Costo total estimado | F8: Total | G8: Rubro (Ingreso/costo/gasto | H8: Cuantas veces se desembolsa la maquina | I8: periodo | J8: Total anual
A9: CELDA ROBÓTICA | H9: 1 | I9: año cero
A10: Robot ABB IRB 1600 + controlador | B10: 1 | C10: unidad (usado, estado aceptable) | E10: 100000000 | F10: =E10*B10 -> 100000000 | G10: Costo | H10: 1 | I10: año cero | J10: =F10*H10 -> 100000000
A11: Cercado / protección de seguridad para celda | B11: 1 | C11: instalación | E11: 10000000 | F11: =E11*B11 -> 10000000 | G11: Costo | H11: 1 | I11: año cero | J11: =F11*H11 -> 10000000
A12: gripper (pinza neumática) | B12: 1 | E12: 4000000 | F12: =E12*B12 -> 4000000 | G12: Costo | H12: 1 | I12: año cero | J12: =F12*H12 -> 4000000
A13: Sistema aire / + accesorios neumáticos | B13: 1 | C13: sistema | E13: 5100000 | F13: =E13*B13 -> 5100000 | G13: Costo | H13: 1 | I13: año cero | J13: =F13*H13 -> 5100000
A14: Compresor para aire / pinza / sistema neumático | B14: 1 | C14: unidad | E14: 8000000 | F14: =E14*B14 -> 8000000 | G14: Costo | H14: 1 | I14: año cero | J14: =F14*H14 -> 8000000
A15: Sistema de seguridad/alarma (sensores, sirena, panel) | B15: 1 | E15: 1500000 | F15: =E15*B15 -> 1500000 | G15: Costo | H15: 1 | I15: año cero | J15: =F15*H15 -> 1500000
A16: Paros de emergencia + cableado | B16: 1 | E16: 650000 | F16: =E16*B16 -> 650000 | G16: Costo | H16: 1 | I16: año cero | J16: =F16*H16 -> 650000
A17: Tablero Electrico | B17: 1 | E17: 2800000 | F17: =E17*B17 -> 2800000 | G17: Costo | H17: 1 | I17: año cero | J17: =F17*H17 -> 2800000
A18: SISTEMA DE PINTADO / MOVIMIENTO LINEAL
A19: Rieles lineales de 2 m + estructura soporte + base giratoria | B19: 1 | C19: set | E19: 4000000 | F19: =E19*B19 -> 4000000 | G19: Costo | H19: 1 | I19: año cero | J19: =F19*H19 -> 4000000
A20: Base giratoria (mesa giratoria metálica / rotatoria) | B20: 1 | C20: unidad | E20: 4000000 | F20: =E20*B20 -> 4000000 | G20: Costo | H20: 1 | I20: año cero | J20: =F20*H20 -> 4000000
A21: tubo conexión compresor | B21: 1 | E21: 200000 | F21: =E21*B21 -> 200000 | G21: Costo | H21: 1 | I21: año cero | J21: =F21*H21 -> 200000
A22: Aspersores / pistolas de pintura + sistema de pintura / mezcla + consumibles | B22: 1 | C22: unidad | E22: 2200000 | F22: =E22*B22 -> 2200000 | G22: Costo | H22: 1 | I22: año cero | J22: =F22*H22 -> 2200000
A23: SISTEMA DE CONTROL
A24: PLC(s) + tarjetas de entrada/salida + módulos I/O | B24: 1 | C24: sistema de control | E24: 4000000 | F24: =E24*B24 -> 4000000 | G24: Costo | H24: 1 | I24: año cero | J24: =F24*H24 -> 4000000
A25: HMI (panel interfaz operador) | B25: 1 | C25: unidad | E25: 5000000 | F25: =E25*B25 -> 5000000 | G25: Costo | H25: 1 | I25: año cero | J25: =F25*H25 -> 5000000
A26: Módulo de comunicación Ethernet/IP | B26: 1 | E26: 3000000 | F26: =E26*B26 -> 3000000 | G26: Costo | H26: 1 | I26: año cero | J26: =F26*H26 -> 3000000
A27: Módulos de E/S digitales | B27: 1 | E27: 4000000 | F27: =E27*B27 -> 4000000 | G27: Costo | H27: 1 | I27: año cero | J27: =F27*H27 -> 4000000
A28: Cables, gabinete, instalación eléctrica / neumática / estructura de control | B28: 1 | E28: 6000000 | F28: =E28*B28 -> 6000000 | G28: Costo | H28: 1 | I28: año cero | J28: =F28*H28 -> 6000000
A29: Fuente de poder 24v 10A | B29: 1 | E29: 300000 | F29: =E29*B29 -> 300000 | G29: Costo | H29: 1 | I29: año cero | J29: =F29*H29 -> 300000
A30: MÁQUINAS A COMPRAR / ADAPTAR (CNC, talladoras, rectificadoras)
A31: Talladoras (2 unidades) | B31: 2 | E31: 15000000 | F31: =E31*B31 -> 30000000 | G31: Costo | H31: 1 | I31: año cero | J31: =F31*H31 -> 30000000
A32: Rectificadoras ( 1 para engranajes) | B32: 1 | E32: 80000000 | F32: =E32*B32 -> 80000000 | G32: Costo | H32: 1 | I32: año cero | J32: =F32*H32 -> 80000000
A34: SENSORES Y ACTUADORES
A35: Actuadores cilindro doble efecto | B35: 3 | E35: 300000 | F35: =E35*B35 -> 900000 | G35: Costo | H35: 1 | I35: año cero | J35: =F35*H35 -> 900000
A36: Ultrasonido 30 cm | B36: 6 | E36: 180000 | F36: =E36*B36 -> 1080000 | G36: Costo | H36: 1 | I36: año cero | J36: =F36*H36 -> 1080000
A37: Valvulas | B37: 5 | E37: 180000 | F37: =E37*B37 -> 900000 | G37: Costo | H37: 1 | I37: año cero | J37: =F37*H37 -> 900000
A39: MECANISMO BANDA
A40: Banda transportadora industrial 70m | B40: 1 | E40: 82500000 | F40: =E40*B40 -> 82500000 | G40: Costo | H40: 1 | I40: año cero | J40: =F40*H40 -> 82500000
A41: Variador para banda transportadora | B41: 1 | E41: 2500000 | F41: =E41*B41 -> 2500000 | G41: Costo | H41: 1 | I41: año cero | J41: =F41*H41 -> 2500000
A43: SOFTWARE
...

Sheet Flujos
A2: Rubro / Ítem | B2: Año cero | C2: 1 | D2: 2 | E2: 3 | F2: 4 | G2: 5 | H2: 6 | I2: 7 | J2: 8 | K2: 9 | L2: 10 | N2: depreciación anual
A3: COSTOS | N3: =B4/10 -> 10000000
A4: Robot ABB IRB 1600 + controlador | B4: =Datos!J10 -> 100000000 | N4: =B5/10 -> 1000000
A5: Cercado / protección de seguridad para celda | B5: =Datos!J11 -> 10000000 | N5: =B6/10 -> 400000
A6: gripper (pinza neumática) | B6: =Datos!J12 -> 4000000 | N6: =B7/10 -> 510000
A7: Sistema aire / + accesorios neumáticos | B7: =Datos!J13 -> 5100000 | N7: =B8/10 -> 800000
A8: Compresor para aire / pinza / sistema neumático | B8: =Datos!J14 -> 8000000 | N8: =B9/10 -> 150000
A9: Sistema de seguridad/alarma (sensores, sirena, panel) | B9: =Datos!J15 -> 1500000 | N9: =B10/10 -> 65000
A10: Paros de emergencia + cableado | B10: =Datos!J16 -> 650000 | N10: =B11/10 -> 280000
A11: Tablero Electrico | B11: =Datos!J17 -> 2800000 | N11: =B12/10 -> 400000
A12: Rieles lineales de 2 m + estructura soporte + base giratoria | B12: =Datos!J19 -> 4000000 | N12: =B13/10 -> 400000
A13: Base giratoria (mesa giratoria metálica / rotatoria) | B13: =Datos!J20 -> 4000000 | N13: =B14/10 -> 20000
A14: tubo conexión compresor | B14: =Datos!J21 -> 200000 | N14: =B15/10 -> 220000
A15: Aspersores / pistolas de pintura + sistema de pintura / mezcla + consumibles | B15: =Datos!J22 -> 2200000 | N15: =B16/10 -> 400000
A16: PLC(s) + tarjetas de entrada/salida + módulos I/O | B16: =Datos!J24 -> 4000000 | N16: =B17/10 -> 500000
A17: HMI (panel interfaz operador) | B17: =Datos!J25 -> 5000000 | N17: =B18/10 -> 300000
A18: Módulo de comunicación Ethernet/IP | B18: =Datos!J26 -> 3000000 | N18: =B19/10 -> 400000
A19: Módulos de E/S digitales | B19: =Datos!J27 -> 4000000 | N19: =B20/10 -> 600000
A20: Cables, gabinete, instalación eléctrica / neumática / estructura de control | B20: =Datos!J28 -> 6000000 | N20: =B21/10 -> 30000
A21: Fuente de poder 24v 10A | B21: =Datos!J29 -> 300000 | N21: =B22/10 -> 3000000
A22: Talladoras (2 unidades) | B22: =Datos!J31 -> 30000000 | N22: =B23/10 -> 8000000
A23: Rectificadoras (2 unidades: 1 para engranajes, 1 para tornillos sin fin) | B23: =Datos!J32 -> 80000000 | N23: =B24/10 -> 90000
A24: Actuadores cilindro doble efecto | B24: =Datos!J35 -> 900000 | N24: =B25/10 -> 108000
A25: Ultrasonido 30 cm | B25: =Datos!J36 -> 1080000 | N25: =B26/10 -> 90000
A26: Valvulas | B26: =Datos!J37 -> 900000 | N26: =B27/10 -> 8250000
A27: Banda transportadora industrial 70m | B27: =Datos!J40 -> 82500000 | N27: =B28/10 -> 250000
A28: Variador para banda transportadora | B28: =Datos!J41 -> 2500000 | N28: =B29/10 -> 600000
A29: Licencia Siemens Tecnomatix | B29: =Datos!J44 -> 6000000 | N29: =B30/10 -> 580000
A30: RobotStudio | B30: =Datos!J45 -> 5800000 | N30: =B31/10 -> 700000
A31: Studio 5000 Logix Designer | B31: =Datos!J46 -> 7000000 | N31: =B32/10 -> 413000
A32: Ignition Maker/Edge + Azure | B32: =Datos!J47 -> 4130000 | N32: =B33/10 -> 3000000
A33: NX Mechatronics | B33: =Datos!J48 -> 30000000 | N33: =B34/10 -> 120000
A34: RSLinx | B34: =Datos!J49 -> 1200000 | N34: =B35/10 -> 7400000
A35: 4 estudiantes | B35: =Datos!$J$73*1.48 -> 74000000
A36: CAPEX | B36: =+SUM(B4:B35) -> 490760000
A40: Producción Sin fin-corona | C40: =Datos!J82 -> 3168000000 | D40: =C40*(1+Datos!$B$3) -> 3.27888e+09 | E40: =D40*(1+Datos!$B$3) -> 3.3936408e+09 | F40: =E40*(1+Datos!$B$3) -> 3.5124182e+09 | G40: =F40*(1+Datos!$B$3) -> 3.6353529e+09 | H40: =G40*(1+Datos!$B$3) -> 3.7625902e+09 | I40: =H40*(1+Datos!$B$3) -> 3.8942809e+09 | J40: =I40*(1+Datos!$B$3) -> 4.0305807e+09 | K40: =J40*(1+Datos!$B$3) -> 4.171651e+09 | L40: =K40*(1+Datos!$B$3) -> 4.3176588e+09
A41: Producción Engranajes conicos | C41: =Datos!J83 -> 2832000000 | D41: =C41*(1+Datos!$B$3) -> 2931120000 | E41: =D41*(1+Datos!$B$3) -> 3033709200 | F41: =E41*(1+Datos!$B$3) -> 3.139889e+09 | G41: =F41*(1+Datos!$B$3) -> 3.2497851e+09 | H41: =G41*(1+Datos!$B$3) -> 3.3635276e+09 | I41: =H41*(1+Datos!$B$3) -> 3.4812511e+09 | J41: =I41*(1+Datos!$B$3) -> 3.6030949e+09 | K41: =J41*(1+Datos!$B$3) -> 3.7292032e+09 | L41: =K41*(1+Datos!$B$3) -> 3.8597253e+09
A42: Producción Engranajes Helicoidales | C42: =Datos!J84 -> 5400000000 | D42: =C42*(1+Datos!$B$3) -> 5589000000 | E42: =D42*(1+Datos!$B$3) -> 5784615000 | F42: =E42*(1+Datos!$B$3) -> 5987076525 | G42: =F42*(1+Datos!$B$3) -> 6.1966242e+09 | H42: =G42*(1+Datos!$B$3) -> 6.4135061e+09 | I42: =H42*(1+Datos!$B$3) -> 6.6379788e+09 | J42: =I42*(1+Datos!$B$3) -> 6.870308e+09 | K42: =J42*(1+Datos!$B$3) -> 7.1107688e+09 | L42: =K42*(1+Datos!$B$3) -> 7.3596457e+09
A43: Trabajador (Tecnico) | C43: =Datos!J53*1.48 -> 227328000 | D43: =C43*(1+Datos!$B$3) -> 2.3528448e+08 | E43: =D43*(1+Datos!$B$3) -> 2.4351944e+08 | F43: =E43*(1+Datos!$B$3) -> 2.5204262e+08 | G43: =F43*(1+Datos!$B$3) -> 2.6086411e+08 | H43: =G43*(1+Datos!$B$3) -> 2.6999435e+08 | I43: =H43*(1+Datos!$B$3) -> 2.7944415e+08 | J43: =I43*(1+Datos!$B$3) -> 2.892247e+08 | K43: =J43*(1+Datos!$B$3) -> 2.9934756e+08 | L43: =K43*(1+Datos!$B$3) -> 3.0982473e+08
A44: Trabajador(Ingeniero Programación) | C44: =Datos!J55*1.48 -> 71040000 | D44: =C44*(1+Datos!$B$3) -> 73526400 | E44: =D44*(1+Datos!$B$3) -> 76099824 | F44: =E44*(1+Datos!$B$3) -> 78763318 | G44: =F44*(1+Datos!$B$3) -> 81520034 | H44: =G44*(1+Datos!$B$3) -> 84373235 | I44: =H44*(1+Datos!$B$3) -> 87326298 | J44: =I44*(1+Datos!$B$3) -> 90382719 | K44: =J44*(1+Datos!$B$3) -> 93546114 | L44: =K44*(1+Datos!$B$3) -> 96820228
...

Sheet Flujo de caja
B2: 0 | C2: 1 | D2: 2 | E2: 3 | F2: 4 | G2: 5 | H2: 6 | I2: 7 | J2: 8 | K2: 9 | L2: 10
A3: INGRESOS | B3: =+Flujos!B63 -> 0 | C3: =+Flujos!C63 -> 13276800000 | D3: =+Flujos!D63 -> 13807872000 | E3: =+Flujos!E63 -> 14360186880 | F3: =+Flujos!F63 -> 1.4934594e+10 | G3: =+Flujos!G63 -> 1.5531978e+10 | H3: =+Flujos!H63 -> 1.6153257e+10 | I3: =+Flujos!I63 -> 1.6799388e+10 | ... L3: =+Flujos!L63 -> 1.8897026e+10
A4: Costos | B4: =+Flujos!B46 -> 0 | C4: =+Flujos!C46*(1+Datos!$B$6) -> 12357878400 | D4: =+Flujos!D46*(1+Datos!$B$6) -> 12790404144 | E4: =+Flujos!E46*(1+Datos!$B$6) -> 1.3238068e+10 | F4: =+Flujos!F46*(1+Datos!$B$6) -> 1.3701401e+10 | G4: =+Flujos!G46*(1+Datos!$B$6) -> 1.418095e+10 | H4: =+Flujos!H46*(1+Datos!$B$6) -> 1.4677283e+10 | I4: =+Flujos!I46*(1+Datos!$B$6) -> 1.5190988e+10 | J4: =+Flujos!J46*(1+Datos!$B$6) -> 1.5722672e+10 | ... L4: =+Flujos!L46*(1+Datos!$B$6) -> 1.684252e+10
A5: Utilidad Bruta | B5: =+B3-B4 -> 0 | C5: =+C3-C4 -> 918921600 | D5: =+D3-D4 -> 1017467856 | E5: =+E3-E4 -> 1.1221186e+09 | F5: =+F3-F4 -> 1.2331937e+09 | G5: =+G3-G4 -> 1.3510284e+09 | H5: =+H3-H4 -> 1.4759743e+09 | I5: =+I3-I4 -> 1.6083997e+09 | ... L5: =+L3-L4 -> 2.0545065e+09
A7: Gastos administrativos | B7: =+Flujos!B57 -> 0 | C7: =+Flujos!C57 -> 899832000 | D7: =+Flujos!D57 -> 931326120 | E7: =+Flujos!E57 -> 9.6392253e+08 | F7: =+Flujos!F57 -> 9.9765982e+08 | G7: =+Flujos!G57 -> 1.0325779e+09 | H7: =+Flujos!H57 -> 1.0687181e+09 | I7: =+Flujos!I57 -> 1.1061233e+09 | ... L7: =+Flujos!L57 -> 1.2263787e+09
A8: EBITDA | B8: =+B5-B7 -> 0 | C8: =+C5-C7 -> 19089600 | D8: =+D5-D7 -> 86141736 | E8: =+E5-E7 -> 1.5819606e+08 | F8: =+F5-F7 -> 2.3553385e+08 | G8: =+G5-G7 -> 3.1845051e+08 | H8: =+H5-H7 -> 4.0725617e+08 | I8: =+I5-I7 -> 5.0227642e+08 | ... L8: =+L5-L7 -> 8.2812786e+08
A10: Depreciación | B10: 0 | C10: =+SUM(Flujos!$N$3:$N$34) -> 49076000 | D10: =+SUM(Flujos!$N$3:$N$34) -> 49076000 | E10: =+SUM(Flujos!$N$3:$N$34) -> 49076000 | F10: =+SUM(Flujos!$N$3:$N$34) -> 49076000 | G10: =+SUM(Flujos!$N$3:$N$34) -> 49076000 | H10: =+SUM(Flujos!$N$3:$N$34) -> 49076000 | I10: =+SUM(Flujos!$N$3:$N$34) -> 49076000 | J10: =+SUM(Flujos!$N$3:$N$34) -> 49076000 | ... L10: =+SUM(Flujos!$N$3:$N$34) -> 49076000
A11: Utilidad Opercional (EBIT) | B11: =+B8-B10 -> 0 | C11: =+C8-C10 -> -29986400 | D11: =+D8-D10 -> 37065736 | E11: =+E8-E10 -> 1.0912006e+08 | F11: =+F8-F10 -> 1.8645785e+08 | G11: =+G8-G10 -> 2.6937451e+08 | H11: =+H8-H10 -> 3.5818017e+08 | I11: =+I8-I10 -> 4.5320042e+08 | ... L11: =+L8-L10 -> 7.7905186e+08
A13: Intereses
A14: Utilidad antes de impuestos(EBT) | B14: =+B11-B13 -> 0 | C14: =+C11-C13 -> -29986400 | D14: =+D11-D13 -> 37065736 | E14: =+E11-E13 -> 1.0912006e+08 | F14: =+F11-F13 -> 1.8645785e+08 | G14: =+G11-G13 -> 2.6937451e+08 | H14: =+H11-H13 -> 3.5818017e+08 | I14: =+I11-I13 -> 4.5320042e+08 | ... L14: =+L11-L13 -> 7.7905186e+08
A16: Impuestos | B16: =+B14*Datos!$B$1 -> 0 | C16: =+C14*Datos!$B$1 -> -10495240 | D16: =+D14*Datos!$B$1 -> 12973008 | E16: =+E14*Datos!$B$1 -> 38192020 | F16: =+F14*Datos!$B$1 -> 65260249 | G16: =+G14*Datos!$B$1 -> 94281078 | H16: =+H14*Datos!$B$1 -> 1.2536306e+08 | I16: =+I14*Datos!$B$1 -> 1.5862015e+08 | ... L16: =+L14*Datos!$B$1 -> 2.7266815e+08
A17: Utilidad neta | B17: =+B14-B16 -> 0 | C17: =+C14-C16 -> -19491160 | D17: =+D14-D16 -> 24092728 | E17: =+E14-E16 -> 70928037 | F17: =+F14-F16 -> 1.211976e+08 | G17: =+G14-G16 -> 1.7509343e+08 | H17: =+H14-H16 -> 2.3281711e+08 | I17: =+I14-I16 -> 2.9458027e+08 | ... L17: =+L14-L16 -> 5.0638371e+08
A19: Depreciación | B19: =+B10 -> 0 | C19: =+C10 -> 49076000 | D19: =+D10 -> 49076000 | E19: =+E10 -> 49076000 | F19: =+F10 -> 49076000 | G19: =+G10 -> 49076000 | H19: =+H10 -> 49076000 | I19: =+I10 -> 49076000 | ... L19: =+L10 -> 49076000
A20: Flujo de caja Operativo | B20: =+B17+B19 -> 0 | C20: =+C17+C19 -> 29584840 | D20: =+D17+D19 -> 73168728 | E20: =+E17+E19 -> 1.2000404e+08 | F20: =+F17+F19 -> 1.702736e+08 | G20: =+G17+G19 -> 2.2416943e+08 | H20: =+H17+H19 -> 2.8189311e+08 | I20: =+I17+I19 -> 3.4365627e+08 | ... L20: =+L17+L19 -> 5.5545971e+08
A22: Capex | B22: =+Flujos!B36 -> 490760000
A24: Flujo Caja Libre | B24: =+B20-B22 -> -490760000 | C24: =+C20-C22 -> 29584840 | D24: =+D20-D22 -> 73168728 | E24: =+E20-E22 -> 1.2000404e+08 | F24: =+F20-F22 -> 1.702736e+08 | G24: =+G20-G22 -> 2.2416943e+08 | H24: =+H20-H22 -> 2.8189311e+08 | I24: =+I20-I22 -> 3.4365627e+08 | ... L24: =+L20-L22 -> 5.5545971e+08
C25: =+C24+B24 -> -461175160 | D25: =+D24+C25 -> -3.8800643e+08 | E25: =+E24+D25 -> -2.6800239e+08 | F25: =+F24+E25 -> -97728790 | G25: =+G24+F25 -> 1.2644064e+08 | H25: =+H24+G25 -> 4.0833375e+08 | I25: =+I24+H25 -> 7.5199002e+08 | J25: =+J24+I25 -> 1.1616711e+09 | K25: =+K24+J25 -> 1.6418718e+09 | L25: =+L24+K25 -> 2.1973315e+09
A27: TIR | B27: =+IRR(B24:L24) -> 0.29947014
A28: Ke | B28: =+'Deuda y ke'!$C$28 -> 0.15805
A29: VNA | B29: =+NPV(B28,C24:L24)+B24 -> 4.9173858e+08
A30: ROI | B30: =-B24/SUM(C24:L24) -> 0.18256819
A31: Payback | B31: =4+-F25/G25 -> 4.7729223
B33: {=+TRANSPOSE('Deuda y ke'!E11:E21)} -> 0 | C33: 29445600 | D33: 28311274 | E33: 26950083 | F33: 25316654 | G33: 23356540 | H33: 21004402 | I33: 18181837 | J33: 14794758 | K33: 10730264 | L33: 5852871.4
A34: Intereses*(1-tx) | B34: =+B33*(1-Datos!$B$1) -> 0 | C34: =+C33*(1-Datos!$B$1) -> 19139640 | D34: =+D33*(1-Datos!$B$1) -> 18402328 | E34: =+E33*(1-Datos!$B$1) -> 17517554 | F34: =+F33*(1-Datos!$B$1) -> 16455825 | G34: =+G33*(1-Datos!$B$1) -> 15181751 | H34: =+H33*(1-Datos!$B$1) -> 13652861 | I34: =+I33*(1-Datos!$B$1) -> 11818194 | ... L34: =+L33*(1-Datos!$B$1) -> 3804366.4
A35: Pago de Capital | B35: {=+TRANSPOSE('Deuda y ke'!F11:F21)} -> 0 | C35: 5671628.5 | D35: 6805954.1 | E35: 8167145 | F35: 9800574 | G35: 11760689 | H35: 14112827 | I35: 16935392 | J35: 20322470 | K35: 24386964 | L35: 29264357
A36: Capital | B36: =+'Deuda y ke'!D4 -> 147228000
A37: Flujo de caja del inversionista | B37: =+B24-B35-B34+B36 -> -343532000 | C37: =+C24-C35-C34+C36 -> 4773571.5 | D37: =+D24-D35-D34+D36 -> 47960446 | E37: =+E24-E35-E34+E36 -> 94319338 | F37: =+F24-F35-F34+F36 -> 1.4401721e+08 | G37: =+G24-G35-G34+G36 -> 1.9722699e+08 | H37: =+H24-H35-H34+H36 -> 2.5412742e+08 | I37: =+I24-I35-I34+I36 -> 3.1490269e+08 | ... L37: =+L24-L35-L34+L36 -> 5.2239098e+08
C38: =+C37+B37 -> -3.3875843e+08 | D38: =+D37+C38 -> -2.9079798e+08 | E38: =+E37+D38 -> -1.9647864e+08 | F38: =+F37+E38 -> -52461440 | G38: =+G37+F38 -> 1.4476555e+08 | H38: =+H37+G38 -> 3.9889297e+08 | I38: =+I37+H38 -> 7.1379566e+08 | J38: =+J37+I38 -> 1.0935377e+09 | K38: =+K37+J38 -> 1.5423767e+09 | L38: =+L37+K38 -> 2.0647677e+09
A40: TIR | B40: =+IRR(B37:L37) -> 0.33831545
A41: Ke | B41: =+'Deuda y ke'!$C$28 -> 0.15805
A42: VNA | B42: =+NPV(B41,C37:L37)+B37 -> 5.0761313e+08
A43: ROI | B43: =-B37/SUM(C37:L37) -> 0.14264504
A44: Payback | B44: =4+-F38/G38 -> 4.362389

Sheet Deuda y ke
B2: CAPEX | C2: =+Flujos!B36 -> 490760000
B4: Deuda | C4: =+Datos!B5 -> 0.3 | D4: =+C2*C4 -> 147228000
B5: Kd | C5: =+Datos!B4 -> 0.2
B6: nper | C6: 10
B7: Cuota | C7: =+PMT(C5,C6,-D4) -> 35117228
B10: Periodo | C10: saldo inicial | D10: cuota | E10: interes | F10: capital | G10: saldo final
B11: 0 | C11: =+D4 -> 147228000 | G11: =+C11-F11 -> 147228000
B12: 1 | C12: =+G11 -> 147228000 | D12: =+$C$7 -> 35117228 | E12: =+C12*$C$5 -> 29445600 | F12: =+D12-E12 -> 5671628.5 | G12: =+C12-F12 -> 1.4155637e+08
B13: 2 | C13: =+G12 -> 1.4155637e+08 | D13: =+$C$7 -> 35117228 | E13: =+C13*$C$5 -> 28311274 | F13: =+D13-E13 -> 6805954.1 | G13: =+C13-F13 -> 1.3475042e+08
B14: 3 | C14: =+G13 -> 1.3475042e+08 | D14: =+$C$7 -> 35117228 | E14: =+C14*$C$5 -> 26950083 | F14: =+D14-E14 -> 8167145 | G14: =+C14-F14 -> 1.2658327e+08
B15: 4 | C15: =+G14 -> 1.2658327e+08 | D15: =+$C$7 -> 35117228 | E15: =+C15*$C$5 -> 25316654 | F15: =+D15-E15 -> 9800574 | G15: =+C15-F15 -> 1.167827e+08
B16: 5 | C16: =+G15 -> 1.167827e+08 | D16: =+$C$7 -> 35117228 | E16: =+C16*$C$5 -> 23356540 | F16: =+D16-E16 -> 11760689 | G16: =+C16-F16 -> 1.0502201e+08
B17: 6 | C17: =+G16 -> 1.0502201e+08 | D17: =+$C$7 -> 35117228 | E17: =+C17*$C$5 -> 21004402 | F17: =+D17-E17 -> 14112827 | G17: =+C17-F17 -> 90909183
B18: 7 | C18: =+G17 -> 90909183 | D18: =+$C$7 -> 35117228 | E18: =+C18*$C$5 -> 18181837 | F18: =+D18-E18 -> 16935392 | G18: =+C18-F18 -> 73973791
B19: 8 | C19: =+G18 -> 73973791 | D19: =+$C$7 -> 35117228 | E19: =+C19*$C$5 -> 14794758 | F19: =+D19-E19 -> 20322470 | G19: =+C19-F19 -> 53651321
B20: 9 | C20: =+G19 -> 53651321 | D20: =+$C$7 -> 35117228 | E20: =+C20*$C$5 -> 10730264 | F20: =+D20-E20 -> 24386964 | G20: =+C20-F20 -> 29264357
B21: 10 | C21: =+G20 -> 29264357 | D21: =+$C$7 -> 35117228 | E21: =+C21*$C$5 -> 5852871.4 | F21: =+D21-E21 -> 29264357 | G21: =+C21-F21 -> 1.6763806e-07
B24: rf | C24: =+Datos!B3 -> 0.035
B25: rm | C25: 0.15
B26: Beta | C26: 1.07
B28: Ke | C28: =+C24+C26*(C25-C24) -> 0.15805
